Workbook

Sheet UFBGA176+25 Ports
A1: Port | B1: Timer 1 | C1: EXTIs | D1: Timer 2 | E1: EXTIs | F1: Timer1 to Timer 2 signal | G1: Timer 2 to Timer 1 signal | H1: SPI or DIAG0/1 | I1: EXTIs | J1: UART A | K1: EXTIs | L1: UART B | M1: EXTIs | N1: CH3/4 Extis
A2: 1 | B2: TIM1 | C2: =_xlfn.XLOOKUP(B2,'UFBFA176+25 Peripherals'!$A:$A,'UFBFA176+25 Peripherals'!$I:$I,"N/A") -> 9,11,13,14 | D2: TIM2 | E2: =_xlfn.XLOOKUP(D2,'UFBFA176+25 Peripherals'!$A:$A,'UFBFA176+25 Peripherals'!$I:$I,"N/A") -> 0,3,10,11 | F2: ITR0 | G2: ITR1 | H2: SPI2 | I2: =_xlfn.XLOOKUP(H2,'UFBFA176+25 Peripherals'!$A:$A,'UFBFA176+25 Peripherals'!$I:$I,"N/A") -> 3,12,14,15 | J2: USART1 | K2: =_xlfn.XLOOKUP(J2,'UFBFA176+25 Peripherals'!$A:$A,'UFBFA176+25 Peripherals'!$I:$I,"N/A") -> 9,10 | L2: UART8 | M2: =_xlfn.XLOOKUP(L2,'UFBFA176+25 Peripherals'!$A:$A,'UFBFA176+25 Peripherals'!$I:$I,"N/A") -> 0,1 | N2: =_xlfn.TEXTJOIN(",",,_xlfn.TAKE(_xlfn.TEXTSPLIT(C2,","),,-2),_xlfn.TAKE(_xlfn.TEXTSPLIT(E2,","),,-2)) -> 13,14,10,11
A3: 2 | B3: TIM3 | C3: =_xlfn.XLOOKUP(B3,'UFBFA176+25 Peripherals'!$A:$A,'UFBFA176+25 Peripherals'!$I:$I,"N/A") -> 0,1,5,6 | D3: TIM24 | E3: =_xlfn.XLOOKUP(D3,'UFBFA176+25 Peripherals'!$A:$A,'UFBFA176+25 Peripherals'!$I:$I,"N/A") -> 11,12,13,14 | F3: ITR2 | G3: ITR12 | H3: SPI4 | I3: =_xlfn.XLOOKUP(H3,'UFBFA176+25 Peripherals'!$A:$A,'UFBFA176+25 Peripherals'!$I:$I,"N/A") -> 4,5,6,12 | J3: USART3 | K3: =_xlfn.XLOOKUP(J3,'UFBFA176+25 Peripherals'!$A:$A,'UFBFA176+25 Peripherals'!$I:$I,"N/A") -> 8,9 | L3: USART2 | M3: =_xlfn.XLOOKUP(L3,'UFBFA176+25 Peripherals'!$A:$A,'UFBFA176+25 Peripherals'!$I:$I,"N/A") -> 5,6 | N3: =_xlfn.TEXTJOIN(",",,_xlfn.TAKE(_xlfn.TEXTSPLIT(C3,","),,-2),_xlfn.TAKE(_xlfn.TEXTSPLIT(E3,","),,-2)) -> 5,6,13,14
A4: 3 | B4: TIM8 | C4: =_xlfn.XLOOKUP(B4,'UFBFA176+25 Peripherals'!$A:$A,'UFBFA176+25 Peripherals'!$I:$I,"N/A") -> 6,7,8,9 | D4: TIM5 | E4: =_xlfn.XLOOKUP(D4,'UFBFA176+25 Peripherals'!$A:$A,'UFBFA176+25 Peripherals'!$I:$I,"N/A") -> 3,10,11,12 | F4: ITR1 | G4: ITR3 | H4: SPI3 | I4: =_xlfn.XLOOKUP(H4,'UFBFA176+25 Peripherals'!$A:$A,'UFBFA176+25 Peripherals'!$I:$I,"N/A") -> 2,10,11,15 | J4: UART5 | K4: =_xlfn.XLOOKUP(J4,'UFBFA176+25 Peripherals'!$A:$A,'UFBFA176+25 Peripherals'!$I:$I,"N/A") -> 2,12 | L4: USART10 | M4: =_xlfn.XLOOKUP(L4,'UFBFA176+25 Peripherals'!$A:$A,'UFBFA176+25 Peripherals'!$I:$I,"N/A") -> 2,3 | N4: =_xlfn.TEXTJOIN(",",,_xlfn.TAKE(_xlfn.TEXTSPLIT(C4,","),,-2),_xlfn.TAKE(_xlfn.TEXTSPLIT(E4,","),,-2)) -> 8,9,11,12
A5: 4 | B5: TIM4 | C5: =_xlfn.XLOOKUP(B5,'UFBFA176+25 Peripherals'!$A:$A,'UFBFA176+25 Peripherals'!$I:$I,"N/A") -> 6,7,14,15 | D5: TIM23 | E5: =_xlfn.XLOOKUP(D5,'UFBFA176+25 Peripherals'!$A:$A,'UFBFA176+25 Peripherals'!$I:$I,"N/A") -> 0,1,2,3 | F5: ITR3 | G5: ITR13 | H5: SPI5 | I5: =_xlfn.XLOOKUP(H5,'UFBFA176+25 Peripherals'!$A:$A,'UFBFA176+25 Peripherals'!$I:$I,"N/A") -> 6,6,8,9 | J5: UART9 | K5: =_xlfn.XLOOKUP(J5,'UFBFA176+25 Peripherals'!$A:$A,'UFBFA176+25 Peripherals'!$I:$I,"N/A") -> 0,1 | L5: UART7 | M5: =_xlfn.XLOOKUP(L5,'UFBFA176+25 Peripherals'!$A:$A,'UFBFA176+25 Peripherals'!$I:$I,"N/A") -> 7,8 | N5: =_xlfn.TEXTJOIN(",",,_xlfn.TAKE(_xlfn.TEXTSPLIT(C5,","),,-2),_xlfn.TAKE(_xlfn.TEXTSPLIT(E5,","),,-2)) -> 14,15,2,3
A7: ALL UART B EXTIS are usable when using SPI, a single UART or timers for comms
A8: All Timer 1's have interconnects to Timer 2's (Table 94, Peripheral interconnect matrix details)
A9: All used EXTIs: | C9: ='UFBFA176+25 Peripherals'!B97 -> 0,1,2,3,4,5,6,7,8,9,13,14,15
A10: Port 1 and 3 have higher priority UART EXTIs than Port 2 and 4
A12: Scenarios
A13: 1 | B13: Two large TYPE A cards plugged into ports 1/2 and 3/4.
A14: 2 | B14: 2x TYPE B cards plugged into port 1 and 3 + 2x TYPE C cards plugged into port 2 and 4
A15: 3 | B15: 4x TYPE C cards plugged into ports 1-4
A16: 4 | B16: 4x TYPE D cards plugged into ports 1-4
A17: 5 | B17: 2x TYPE E cards plugged into ports 2 and 4
B18: Other variations/combinations possible with some signals going to the FPGA instead of the MCU.
A20: TYPE A | B20: 1 advanced timer, 1 normal timer, 2x32 bit timers with 4 encoders, 2 SPI + 2 HW NSS, 2 UARTS
A21: TYPE B | B21: advanced timer, 32 bit timer, 2 encoders, 1 spi, 1 HW NSS, 2 uarts
A22: TYPE C | B22: normal timer, 32 bit timer, 2 encoders, 1 spi, 1 HW NSS, 2 uarts
A23: TYPE D | B23: normal timer, 32 bit timer, 2 encoders, 1 spi, 1 HW NSS, 1 uart, 2 exti | H23: 2xTMC5160 | I23: Encoder signals go to TMC5160
A24: TYPE E | B24: 2 uarts, 2 ABN encoders,bit-bash/MDMA 2 pairs of step/dir on spi pins | H24: 2xTMC2209 | I24: ABN encoder signals on CH1/2/4 or FPGA encoders, use 2nd UART for 2xEXTI (2xDIAG0), FPGA for index.
A27: Remarks
B28: FPGA and MCU share a flash chip. MCU must not drive signals when FPGA boots, SS needs to be correct on boot to tell FPGA how to use the SPI, Flash WP and HOLD need to be correct too.
B29: Flash is programmed by the MCU, via OCTOSPI.
B30: Flash can be used by the MCU after the FPGA has booted, memory mapped if needed.
B31: Backup FPGA images, configuration data and other stuff can be stored on the flash.
B32: MCU can communicate with FPGA using SPI pins once FPGA is booted, as long as the FPGA implements an SPI peripheral on the same pins.
B33: Need LED on the CDONE signal
B34: Need a second SPI CS pin for the FPGA to be able to address either the flash or the FPGA.
B35: Each card can have a small I2C flash chip for identification purposes.
B36: CDONE used as an input while programming, and as an EXTI afterwards, and can have an LED.

Sheet UFBFA176+25 Peripherals
A1: Peripheral/IO | B1: Features | C1: Usage | D1: Pins | H1: Pin numbers | I1: Sorted pin numbers
D2: CH1 | E2: CH2 | F2: CH3 | G2: CH4
A3: TIM1 | B3: Advanced,Encoder,16bit,DMA,4CH | C3: Port 1 Encoder A/B/N + NSS2 | D3: =_xlfn.XLOOKUP(_xlfn.CONCAT($A3,"_",D$2),'UFBGA176+25 GPIOs'!$B$1:$B$133,'UFBGA176+25 GPIOs'!$A$1:$A$133,"NONE") -> PE9 | E3: =_xlfn.XLOOKUP(_xlfn.CONCAT($A3,"_",E$2),'UFBGA176+25 GPIOs'!$B$1:$B$133,'UFBGA176+25 GPIOs'!$A$1:$A$133,"NONE") -> PE11 | F3: =_xlfn.XLOOKUP(_xlfn.CONCAT($A3,"_",F$2),'UFBGA176+25 GPIOs'!$B$1:$B$133,'UFBGA176+25 GPIOs'!$A$1:$A$133,"NONE") -> PE13 | G3: =_xlfn.XLOOKUP(_xlfn.CONCAT($A3,"_",G$2),'UFBGA176+25 GPIOs'!$B$1:$B$133,'UFBGA176+25 GPIOs'!$A$1:$A$133,"NONE") -> PE14 | H3: {=_xlfn.LET( _xlpm.joined, _xlfn.TEXTJOIN(",", TRUE, D3:G3), _xlpm.cleaned, _xlfn.TEXTJOIN("", TRUE, IF( (ISNUMBER(--MID(_xlpm.joined, _xlfn.SEQUENCE(LEN(_xlpm.joined)), 1))) + (MID(_xlpm.joined, _xlfn.SEQUENCE(LEN(_xlpm.joined)), 1) = ","), MID(_xlpm.joined, _xlfn.SEQUENCE(LEN(_xlpm.joined)), 1), "" ) ), IFERROR( _xlfn.TEXTJOIN(",", TRUE, _xlfn._xlws.FILTER(_xlfn.TEXTSPLIT(_xlpm.cleaned, ","), _xlfn.TEXTSPLIT(_xlpm.cleaned, ",")<>"") ), "" ) )} -> 9,11,13,14 | I3: {=IF( H3="", "", _xlfn.TEXTJOIN( ",", TRUE, _xlfn.SORTBY( _xlfn._xlws.FILTER(--TRIM(_xlfn.TEXTSPLIT(H3, ",")), ISNUMBER(--TRIM(_xlfn.TEXTSPLIT(H3, ",")))), --_xlfn._xlws.FILTER(--TRIM(_xlfn.TEXTSPLIT(H3, ",")), ISNUMBER(--TRIM(_xlfn.TEXTSPLIT(H3, ",")))) ) ) )} -> 9,11,13,14
A4: TIM2 | B4: Encoder,32bit,DMA,4CH | C4: Step/Dir/Step/Dir | D4: =_xlfn.XLOOKUP(_xlfn.CONCAT($A4,"_",D$2),'UFBGA176+25 GPIOs'!$B$1:$B$133,'UFBGA176+25 GPIOs'!$A$1:$A$133,"NONE") -> PA0 | E4: =_xlfn.XLOOKUP(_xlfn.CONCAT($A4,"_",E$2),'UFBGA176+25 GPIOs'!$B$1:$B$133,'UFBGA176+25 GPIOs'!$A$1:$A$133,"NONE") -> PB3(JTDO/TRACESWO) | F4: =_xlfn.XLOOKUP(_xlfn.CONCAT($A4,"_",F$2),'UFBGA176+25 GPIOs'!$B$1:$B$133,'UFBGA176+25 GPIOs'!$A$1:$A$133,"NONE") -> PB10 | G4: =_xlfn.XLOOKUP(_xlfn.CONCAT($A4,"_",G$2),'UFBGA176+25 GPIOs'!$B$1:$B$133,'UFBGA176+25 GPIOs'!$A$1:$A$133,"NONE") -> PB11 | H4: {=_xlfn.LET( _xlpm.joined, _xlfn.TEXTJOIN(",", TRUE, D4:G4), _xlpm.cleaned, _xlfn.TEXTJOIN("", TRUE, IF( (ISNUMBER(--MID(_xlpm.joined, _xlfn.SEQUENCE(LEN(_xlpm.joined)), 1))) + (MID(_xlpm.joined, _xlfn.SEQUENCE(LEN(_xlpm.joined)), 1) = ","), MID(_xlpm.joined, _xlfn.SEQUENCE(LEN(_xlpm.joined)), 1), "" ) ), IFERROR( _xlfn.TEXTJOIN(",", TRUE, _xlfn._xlws.FILTER(_xlfn.TEXTSPLIT(_xlpm.cleaned, ","), _xlfn.TEXTSPLIT(_xlpm.cleaned, ",")<>"") ), "" ) )} -> 0,3,10,11 | I4: {=IF( H4="", "", _xlfn.TEXTJOIN( ",", TRUE, _xlfn.SORTBY( _xlfn._xlws.FILTER(--TRIM(_xlfn.TEXTSPLIT(H4, ",")), ISNUMBER(--TRIM(_xlfn.TEXTSPLIT(H4, ",")))), --_xlfn._xlws.FILTER(--TRIM(_xlfn.TEXTSPLIT(H4, ",")), ISNUMBER(--TRIM(_xlfn.TEXTSPLIT(H4, ",")))) ) ) )} -> 0,3,10,11
A5: TIM3 | B5: Encoder,16bit,DMA,4CH | C5: Port 2 Encoder A/B/N + NSS2 | D5: =_xlfn.XLOOKUP(_xlfn.CONCAT($A5,"_",D$2),'UFBGA176+25 GPIOs'!$B$1:$B$133,'UFBGA176+25 GPIOs'!$A$1:$A$133,"NONE") -> PA6 | E5: =_xlfn.XLOOKUP(_xlfn.CONCAT($A5,"_",E$2),'UFBGA176+25 GPIOs'!$B$1:$B$133,'UFBGA176+25 GPIOs'!$A$1:$A$133,"NONE") -> PB5 | F5: =_xlfn.XLOOKUP(_xlfn.CONCAT($A5,"_",F$2),'UFBGA176+25 GPIOs'!$B$1:$B$133,'UFBGA176+25 GPIOs'!$A$1:$A$133,"NONE") -> PB0 | G5: =_xlfn.XLOOKUP(_xlfn.CONCAT($A5,"_",G$2),'UFBGA176+25 GPIOs'!$B$1:$B$133,'UFBGA176+25 GPIOs'!$A$1:$A$133,"NONE") -> PB1 | H5: {=_xlfn.LET( _xlpm.joined, _xlfn.TEXTJOIN(",", TRUE, D5:G5), _xlpm.cleaned, _xlfn.TEXTJOIN("", TRUE, IF( (ISNUMBER(--MID(_xlpm.joined, _xlfn.SEQUENCE(LEN(_xlpm.joined)), 1))) + (MID(_xlpm.joined, _xlfn.SEQUENCE(LEN(_xlpm.joined)), 1) = ","), MID(_xlpm.joined, _xlfn.SEQUENCE(LEN(_xlpm.joined)), 1), "" ) ), IFERROR( _xlfn.TEXTJOIN(",", TRUE, _xlfn._xlws.FILTER(_xlfn.TEXTSPLIT(_xlpm.cleaned, ","), _xlfn.TEXTSPLIT(_xlpm.cleaned, ",")<>"") ), "" ) )} -> 6,5,0,1 | I5: {=IF( H5="", "", _xlfn.TEXTJOIN( ",", TRUE, _xlfn.SORTBY( _xlfn._xlws.FILTER(--TRIM(_xlfn.TEXTSPLIT(H5, ",")), ISNUMBER(--TRIM(_xlfn.TEXTSPLIT(H5, ",")))), --_xlfn._xlws.FILTER(--TRIM(_xlfn.TEXTSPLIT(H5, ",")), ISNUMBER(--TRIM(_xlfn.TEXTSPLIT(H5, ",")))) ) ) )} -> 0,1,5,6
A6: TIM4 | B6: Encoder,16bit,DMA,4CH | C6: Port 4 Encoder A/B/N + NSS2 | D6: =_xlfn.XLOOKUP(_xlfn.CONCAT($A6,"_",D$2),'UFBGA176+25 GPIOs'!$B$1:$B$133,'UFBGA176+25 GPIOs'!$A$1:$A$133,"NONE") -> PB6 | E6: =_xlfn.XLOOKUP(_xlfn.CONCAT($A6,"_",E$2),'UFBGA176+25 GPIOs'!$B$1:$B$133,'UFBGA176+25 GPIOs'!$A$1:$A$133,"NONE") -> PB7 | F6: =_xlfn.XLOOKUP(_xlfn.CONCAT($A6,"_",F$2),'UFBGA176+25 GPIOs'!$B$1:$B$133,'UFBGA176+25 GPIOs'!$A$1:$A$133,"NONE") -> PD14 | G6: =_xlfn.XLOOKUP(_xlfn.CONCAT($A6,"_",G$2),'UFBGA176+25 GPIOs'!$B$1:$B$133,'UFBGA176+25 GPIOs'!$A$1:$A$133,"NONE") -> PD15 | H6: {=_xlfn.LET( _xlpm.joined, _xlfn.TEXTJOIN(",", TRUE, D6:G6), _xlpm.cleaned, _xlfn.TEXTJOIN("", TRUE, IF( (ISNUMBER(--MID(_xlpm.joined, _xlfn.SEQUENCE(LEN(_xlpm.joined)), 1))) + (MID(_xlpm.joined, _xlfn.SEQUENCE(LEN(_xlpm.joined)), 1) = ","), MID(_xlpm.joined, _xlfn.SEQUENCE(LEN(_xlpm.joined)), 1), "" ) ), IFERROR( _xlfn.TEXTJOIN(",", TRUE, _xlfn._xlws.FILTER(_xlfn.TEXTSPLIT(_xlpm.cleaned, ","), _xlfn.TEXTSPLIT(_xlpm.cleaned, ",")<>"") ), "" ) )} -> 6,7,14,15 | I6: {=IF( H6="", "", _xlfn.TEXTJOIN( ",", TRUE, _xlfn.SORTBY( _xlfn._xlws.FILTER(--TRIM(_xlfn.TEXTSPLIT(H6, ",")), ISNUMBER(--TRIM(_xlfn.TEXTSPLIT(H6, ",")))), --_xlfn._xlws.FILTER(--TRIM(_xlfn.TEXTSPLIT(H6, ",")), ISNUMBER(--TRIM(_xlfn.TEXTSPLIT(H6, ",")))) ) ) )} -> 6,7,14,15
A7: TIM5 | B7: Encoder,32bit,DMA,4CH | C7: Step/Dir/Step/Dir | D7: =_xlfn.XLOOKUP(_xlfn.CONCAT($A7,"_",D$2),'UFBGA176+25 GPIOs'!$B$1:$B$133,'UFBGA176+25 GPIOs'!$A$1:$A$133,"NONE") -> PH10 | E7: =_xlfn.XLOOKUP(_xlfn.CONCAT($A7,"_",E$2),'UFBGA176+25 GPIOs'!$B$1:$B$133,'UFBGA176+25 GPIOs'!$A$1:$A$133,"NONE") -> PH11 | F7: =_xlfn.XLOOKUP(_xlfn.CONCAT($A7,"_",F$2),'UFBGA176+25 GPIOs'!$B$1:$B$133,'UFBGA176+25 GPIOs'!$A$1:$A$133,"NONE") -> PH12 | G7: =_xlfn.XLOOKUP(_xlfn.CONCAT($A7,"_",G$2),'UFBGA176+25 GPIOs'!$B$1:$B$133,'UFBGA176+25 GPIOs'!$A$1:$A$133,"NONE") -> PA3 | H7: {=_xlfn.LET( _xlpm.joined, _xlfn.TEXTJOIN(",", TRUE, D7:G7), _xlpm.cleaned, _xlfn.TEXTJOIN("", TRUE, IF( (ISNUMBER(--MID(_xlpm.joined, _xlfn.SEQUENCE(LEN(_xlpm.joined)), 1))) + (MID(_xlpm.joined, _xlfn.SEQUENCE(LEN(_xlpm.joined)), 1) = ","), MID(_xlpm.joined, _xlfn.SEQUENCE(LEN(_xlpm.joined)), 1), "" ) ), IFERROR( _xlfn.TEXTJOIN(",", TRUE, _xlfn._xlws.FILTER(_xlfn.TEXTSPLIT(_xlpm.cleaned, ","), _xlfn.TEXTSPLIT(_xlpm.cleaned, ",")<>"") ), "" ) )} -> 10,11,12,3 | I7: {=IF( H7="", "", _xlfn.TEXTJOIN( ",", TRUE, _xlfn.SORTBY( _xlfn._xlws.FILTER(--TRIM(_xlfn.TEXTSPLIT(H7, ",")), ISNUMBER(--TRIM(_xlfn.TEXTSPLIT(H7, ",")))), --_xlfn._xlws.FILTER(--TRIM(_xlfn.TEXTSPLIT(H7, ",")), ISNUMBER(--TRIM(_xlfn.TEXTSPLIT(H7, ",")))) ) ) )} -> 3,10,11,12
A8: TIM6 | B8: DMA,DAC | C8: DAC | D8: =_xlfn.XLOOKUP("DAC1_OUT1",'UFBGA176+25 GPIOs'!$B$1:$B$133,'UFBGA176+25 GPIOs'!$A$1:$A$133) -> PA4 | H8: {=_xlfn.LET( _xlpm.joined, _xlfn.TEXTJOIN(",", TRUE, D8:G8), _xlpm.cleaned, _xlfn.TEXTJOIN("", TRUE, IF( (ISNUMBER(--MID(_xlpm.joined, _xlfn.SEQUENCE(LEN(_xlpm.joined)), 1))) + (MID(_xlpm.joined, _xlfn.SEQUENCE(LEN(_xlpm.joined)), 1) = ","), MID(_xlpm.joined, _xlfn.SEQUENCE(LEN(_xlpm.joined)), 1), "" ) ), IFERROR( _xlfn.TEXTJOIN(",", TRUE, _xlfn._xlws.FILTER(_xlfn.TEXTSPLIT(_xlpm.cleaned, ","), _xlfn.TEXTSPLIT(_xlpm.cleaned, ",")<>"") ), "" ) )} -> 4 | I8: {=IF( H8="", "", _xlfn.TEXTJOIN( ",", TRUE, _xlfn.SORTBY( _xlfn._xlws.FILTER(--TRIM(_xlfn.TEXTSPLIT(H8, ",")), ISNUMBER(--TRIM(_xlfn.TEXTSPLIT(H8, ",")))), --_xlfn._xlws.FILTER(--TRIM(_xlfn.TEXTSPLIT(H8, ",")), ISNUMBER(--TRIM(_xlfn.TEXTSPLIT(H8, ",")))) ) ) )} -> 4
A9: TIM7 | B9: DMA,DAC | C9: DAC | D9: =_xlfn.XLOOKUP("DAC1_OUT2",'UFBGA176+25 GPIOs'!$B$1:$B$133,'UFBGA176+25 GPIOs'!$A$1:$A$133) -> #N/A | H9: {=_xlfn.LET( _xlpm.joined, _xlfn.TEXTJOIN(",", TRUE, D9:G9), _xlpm.cleaned, _xlfn.TEXTJOIN("", TRUE, IF( (ISNUMBER(--MID(_xlpm.joined, _xlfn.SEQUENCE(LEN(_xlpm.joined)), 1))) + (MID(_xlpm.joined, _xlfn.SEQUENCE(LEN(_xlpm.joined)), 1) = ","), MID(_xlpm.joined, _xlfn.SEQUENCE(LEN(_xlpm.joined)), 1), "" ) ), IFERROR( _xlfn.TEXTJOIN(",", TRUE, _xlfn._xlws.FILTER(_xlfn.TEXTSPLIT(_xlpm.cleaned, ","), _xlfn.TEXTSPLIT(_xlpm.cleaned, ",")<>"") ), "" ) )} | I9: {=IF( H9="", "", _xlfn.TEXTJOIN( ",", TRUE, _xlfn.SORTBY( _xlfn._xlws.FILTER(--TRIM(_xlfn.TEXTSPLIT(H9, ",")), ISNUMBER(--TRIM(_xlfn.TEXTSPLIT(H9, ",")))), --_xlfn._xlws.FILTER(--TRIM(_xlfn.TEXTSPLIT(H9, ",")), ISNUMBER(--TRIM(_xlfn.TEXTSPLIT(H9, ",")))) ) ) )}
A10: TIM8 | B10: Advanced,Encoder,16bit,DMA,4CH | C10: Port 3 Encoder A/B/N + NSS2 | D10: =_xlfn.XLOOKUP(_xlfn.CONCAT($A10,"_",D$2),'UFBGA176+25 GPIOs'!$B$1:$B$133,'UFBGA176+25 GPIOs'!$A$1:$A$133,"NONE") -> PC6 | E10: =_xlfn.XLOOKUP(_xlfn.CONCAT($A10,"_",E$2),'UFBGA176+25 GPIOs'!$B$1:$B$133,'UFBGA176+25 GPIOs'!$A$1:$A$133,"NONE") -> PC7 | F10: =_xlfn.XLOOKUP(_xlfn.CONCAT($A10,"_",F$2),'UFBGA176+25 GPIOs'!$B$1:$B$133,'UFBGA176+25 GPIOs'!$A$1:$A$133,"NONE") -> PC8 | G10: =_xlfn.XLOOKUP(_xlfn.CONCAT($A10,"_",G$2),'UFBGA176+25 GPIOs'!$B$1:$B$133,'UFBGA176+25 GPIOs'!$A$1:$A$133,"NONE") -> PC9 | H10: {=_xlfn.LET( _xlpm.joined, _xlfn.TEXTJOIN(",", TRUE, D10:G10), _xlpm.cleaned, _xlfn.TEXTJOIN("", TRUE, IF( (ISNUMBER(--MID(_xlpm.joined, _xlfn.SEQUENCE(LEN(_xlpm.joined)), 1))) + (MID(_xlpm.joined, _xlfn.SEQUENCE(LEN(_xlpm.joined)), 1) = ","), MID(_xlpm.joined, _xlfn.SEQUENCE(LEN(_xlpm.joined)), 1), "" ) ), IFERROR( _xlfn.TEXTJOIN(",", TRUE, _xlfn._xlws.FILTER(_xlfn.TEXTSPLIT(_xlpm.cleaned, ","), _xlfn.TEXTSPLIT(_xlpm.cleaned, ",")<>"") ), "" ) )} -> 6,7,8,9 | I10: {=IF( H10="", "", _xlfn.TEXTJOIN( ",", TRUE, _xlfn.SORTBY( _xlfn._xlws.FILTER(--TRIM(_xlfn.TEXTSPLIT(H10, ",")), ISNUMBER(--TRIM(_xlfn.TEXTSPLIT(H10, ",")))), --_xlfn._xlws.FILTER(--TRIM(_xlfn.TEXTSPLIT(H10, ",")), ISNUMBER(--TRIM(_xlfn.TEXTSPLIT(H10, ",")))) ) ) )} -> 6,7,8,9
A11: TIM12 | B11: NoDMA,2CH | C11: Embassy to use no support for TIM6/7/13/14/16/17 | D11: =_xlfn.XLOOKUP(_xlfn.CONCAT($A11,"_",D$2),'UFBGA176+25 GPIOs'!$B$1:$B$133,'UFBGA176+25 GPIOs'!$A$1:$A$133,"NONE") -> NONE | E11: =_xlfn.XLOOKUP(_xlfn.CONCAT($A11,"_",E$2),'UFBGA176+25 GPIOs'!$B$1:$B$133,'UFBGA176+25 GPIOs'!$A$1:$A$133,"NONE") -> NONE | F11: =_xlfn.XLOOKUP(_xlfn.CONCAT($A11,"_",F$2),'UFBGA176+25 GPIOs'!$B$1:$B$133,'UFBGA176+25 GPIOs'!$A$1:$A$133,"NONE") -> NONE | G11: =_xlfn.XLOOKUP(_xlfn.CONCAT($A11,"_",G$2),'UFBGA176+25 GPIOs'!$B$1:$B$133,'UFBGA176+25 GPIOs'!$A$1:$A$133,"NONE") -> NONE | H11: {=_xlfn.LET( _xlpm.joined, _xlfn.TEXTJOIN(",", TRUE, D11:G11), _xlpm.cleaned, _xlfn.TEXTJOIN("", TRUE, IF( (ISNUMBER(--MID(_xlpm.joined, _xlfn.SEQUENCE(LEN(_xlpm.joined)), 1))) + (MID(_xlpm.joined, _xlfn.SEQUENCE(LEN(_xlpm.joined)), 1) = ","), MID(_xlpm.joined, _xlfn.SEQUENCE(LEN(_xlpm.joined)), 1), "" ) ), IFERROR( _xlfn.TEXTJOIN(",", TRUE, _xlfn._xlws.FILTER(_xlfn.TEXTSPLIT(_xlpm.cleaned, ","), _xlfn.TEXTSPLIT(_xlpm.cleaned, ",")<>"") ), "" ) )} | I11: {=IF( H11="", "", _xlfn.TEXTJOIN( ",", TRUE, _xlfn.SORTBY( _xlfn._xlws.FILTER(--TRIM(_xlfn.TEXTSPLIT(H11, ",")), ISNUMBER(--TRIM(_xlfn.TEXTSPLIT(H11, ",")))), --_xlfn._xlws.FILTER(--TRIM(_xlfn.TEXTSPLIT(H11, ",")), ISNUMBER(--TRIM(_xlfn.TEXTSPLIT(H11, ",")))) ) ) )}
A12: TIM13 | B12: NoDMA,1CH | D12: =_xlfn.XLOOKUP(_xlfn.CONCAT($A12,"_",D$2),'UFBGA176+25 GPIOs'!$B$1:$B$133,'UFBGA176+25 GPIOs'!$A$1:$A$133,"NONE") -> NONE | E12: =_xlfn.XLOOKUP(_xlfn.CONCAT($A12,"_",E$2),'UFBGA176+25 GPIOs'!$B$1:$B$133,'UFBGA176+25 GPIOs'!$A$1:$A$133,"NONE") -> NONE | F12: =_xlfn.XLOOKUP(_xlfn.CONCAT($A12,"_",F$2),'UFBGA176+25 GPIOs'!$B$1:$B$133,'UFBGA176+25 GPIOs'!$A$1:$A$133,"NONE") -> NONE | G12: =_xlfn.XLOOKUP(_xlfn.CONCAT($A12,"_",G$2),'UFBGA176+25 GPIOs'!$B$1:$B$133,'UFBGA176+25 GPIOs'!$A$1:$A$133,"NONE") -> NONE | H12: {=_xlfn.LET( _xlpm.joined, _xlfn.TEXTJOIN(",", TRUE, D12:G12), _xlpm.cleaned, _xlfn.TEXTJOIN("", TRUE, IF( (ISNUMBER(--MID(_xlpm.joined, _xlfn.SEQUENCE(LEN(_xlpm.joined)), 1))) + (MID(_xlpm.joined, _xlfn.SEQUENCE(LEN(_xlpm.joined)), 1) = ","), MID(_xlpm.joined, _xlfn.SEQUENCE(LEN(_xlpm.joined)), 1), "" ) ), IFERROR( _xlfn.TEXTJOIN(",", TRUE, _xlfn._xlws.FILTER(_xlfn.TEXTSPLIT(_xlpm.cleaned, ","), _xlfn.TEXTSPLIT(_xlpm.cleaned, ",")<>"") ), "" ) )} | I12: {=IF( H12="", "", _xlfn.TEXTJOIN( ",", TRUE, _xlfn.SORTBY( _xlfn._xlws.FILTER(--TRIM(_xlfn.TEXTSPLIT(H12, ",")), ISNUMBER(--TRIM(_xlfn.TEXTSPLIT(H12, ",")))), --_xlfn._xlws.FILTER(--TRIM(_xlfn.TEXTSPLIT(H12, ",")), ISNUMBER(--TRIM(_xlfn.TEXTSPLIT(H12, ",")))) ) ) )}
A13: TIM14 | B13: NoDMA,1CH | D13: =_xlfn.XLOOKUP(_xlfn.CONCAT($A13,"_",D$2),'UFBGA176+25 GPIOs'!$B$1:$B$133,'UFBGA176+25 GPIOs'!$A$1:$A$133,"NONE") -> NONE | E13: =_xlfn.XLOOKUP(_xlfn.CONCAT($A13,"_",E$2),'UFBGA176+25 GPIOs'!$B$1:$B$133,'UFBGA176+25 GPIOs'!$A$1:$A$133,"NONE") -> NONE | F13: =_xlfn.XLOOKUP(_xlfn.CONCAT($A13,"_",F$2),'UFBGA176+25 GPIOs'!$B$1:$B$133,'UFBGA176+25 GPIOs'!$A$1:$A$133,"NONE") -> NONE | G13: =_xlfn.XLOOKUP(_xlfn.CONCAT($A13,"_",G$2),'UFBGA176+25 GPIOs'!$B$1:$B$133,'UFBGA176+25 GPIOs'!$A$1:$A$133,"NONE") -> NONE | H13: {=_xlfn.LET( _xlpm.joined, _xlfn.TEXTJOIN(",", TRUE, D13:G13), _xlpm.cleaned, _xlfn.TEXTJOIN("", TRUE, IF( (ISNUMBER(--MID(_xlpm.joined, _xlfn.SEQUENCE(LEN(_xlpm.joined)), 1))) + (MID(_xlpm.joined, _xlfn.SEQUENCE(LEN(_xlpm.joined)), 1) = ","), MID(_xlpm.joined, _xlfn.SEQUENCE(LEN(_xlpm.joined)), 1), "" ) ), IFERROR( _xlfn.TEXTJOIN(",", TRUE, _xlfn._xlws.FILTER(_xlfn.TEXTSPLIT(_xlpm.cleaned, ","), _xlfn.TEXTSPLIT(_xlpm.cleaned, ",")<>"") ), "" ) )} | I13: {=IF( H13="", "", _xlfn.TEXTJOIN( ",", TRUE, _xlfn.SORTBY( _xlfn._xlws.FILTER(--TRIM(_xlfn.TEXTSPLIT(H13, ",")), ISNUMBER(--TRIM(_xlfn.TEXTSPLIT(H13, ",")))), --_xlfn._xlws.FILTER(--TRIM(_xlfn.TEXTSPLIT(H13, ",")), ISNUMBER(--TRIM(_xlfn.TEXTSPLIT(H13, ",")))) ) ) )}
A14: TIM15 | B14: DMA,2CH | C14: Use to drive MDMA to generate 16 step/dir signals on SPI pins | D14: =_xlfn.XLOOKUP(_xlfn.CONCAT($A14,"_",D$2),'UFBGA176+25 GPIOs'!$B$1:$B$133,'UFBGA176+25 GPIOs'!$A$1:$A$133,"NONE") -> NONE | E14: =_xlfn.XLOOKUP(_xlfn.CONCAT($A14,"_",E$2),'UFBGA176+25 GPIOs'!$B$1:$B$133,'UFBGA176+25 GPIOs'!$A$1:$A$133,"NONE") -> NONE | F14: =_xlfn.XLOOKUP(_xlfn.CONCAT($A14,"_",F$2),'UFBGA176+25 GPIOs'!$B$1:$B$133,'UFBGA176+25 GPIOs'!$A$1:$A$133,"NONE") -> NONE | G14: =_xlfn.XLOOKUP(_xlfn.CONCAT($A14,"_",G$2),'UFBGA176+25 GPIOs'!$B$1:$B$133,'UFBGA176+25 GPIOs'!$A$1:$A$133,"NONE") -> NONE | H14: {=_xlfn.LET( _xlpm.joined, _xlfn.TEXTJOIN(",", TRUE, D14:G14), _xlpm.cleaned, _xlfn.TEXTJOIN("", TRUE, IF( (ISNUMBER(--MID(_xlpm.joined, _xlfn.SEQUENCE(LEN(_xlpm.joined)), 1))) + (MID(_xlpm.joined, _xlfn.SEQUENCE(LEN(_xlpm.joined)), 1) = ","), MID(_xlpm.joined, _xlfn.SEQUENCE(LEN(_xlpm.joined)), 1), "" ) ), IFERROR( _xlfn.TEXTJOIN(",", TRUE, _xlfn._xlws.FILTER(_xlfn.TEXTSPLIT(_xlpm.cleaned, ","), _xlfn.TEXTSPLIT(_xlpm.cleaned, ",")<>"") ), "" ) )} | I14: {=IF( H14="", "", _xlfn.TEXTJOIN( ",", TRUE, _xlfn.SORTBY( _xlfn._xlws.FILTER(--TRIM(_xlfn.TEXTSPLIT(H14, ",")), ISNUMBER(--TRIM(_xlfn.TEXTSPLIT(H14, ",")))), --_xlfn._xlws.FILTER(--TRIM(_xlfn.TEXTSPLIT(H14, ",")), ISNUMBER(--TRIM(_xlfn.TEXTSPLIT(H14, ",")))) ) ) )}
A15: TIM16 | B15: DMA,1CH | C15: Port 2 / EXPANSION PORT | D15: =_xlfn.XLOOKUP(_xlfn.CONCAT($A15,"_",D$2),'UFBGA176+25 GPIOs'!$B$1:$B$133,'UFBGA176+25 GPIOs'!$A$1:$A$133,"NONE") -> PB8 | E15: =_xlfn.XLOOKUP(_xlfn.CONCAT($A15,"_",E$2),'UFBGA176+25 GPIOs'!$B$1:$B$133,'UFBGA176+25 GPIOs'!$A$1:$A$133,"NONE") -> NONE | F15: =_xlfn.XLOOKUP(_xlfn.CONCAT($A15,"_",F$2),'UFBGA176+25 GPIOs'!$B$1:$B$133,'UFBGA176+25 GPIOs'!$A$1:$A$133,"NONE") -> NONE | G15: =_xlfn.XLOOKUP(_xlfn.CONCAT($A15,"_",G$2),'UFBGA176+25 GPIOs'!$B$1:$B$133,'UFBGA176+25 GPIOs'!$A$1:$A$133,"NONE") -> NONE | H15: {=_xlfn.LET( _xlpm.joined, _xlfn.TEXTJOIN(",", TRUE, D15:G15), _xlpm.cleaned, _xlfn.TEXTJOIN("", TRUE, IF( (ISNUMBER(--MID(_xlpm.joined, _xlfn.SEQUENCE(LEN(_xlpm.joined)), 1))) + (MID(_xlpm.joined, _xlfn.SEQUENCE(LEN(_xlpm.joined)), 1) = ","), MID(_xlpm.joined, _xlfn.SEQUENCE(LEN(_xlpm.joined)), 1), "" ) ), IFERROR( _xlfn.TEXTJOIN(",", TRUE, _xlfn._xlws.FILTER(_xlfn.TEXTSPLIT(_xlpm.cleaned, ","), _xlfn.TEXTSPLIT(_xlpm.cleaned, ",")<>"") ), "" ) )} -> 8 | I15: {=IF( H15="", "", _xlfn.TEXTJOIN( ",", TRUE, _xlfn.SORTBY( _xlfn._xlws.FILTER(--TRIM(_xlfn.TEXTSPLIT(H15, ",")), ISNUMBER(--TRIM(_xlfn.TEXTSPLIT(H15, ",")))), --_xlfn._xlws.FILTER(--TRIM(_xlfn.TEXTSPLIT(H15, ",")), ISNUMBER(--TRIM(_xlfn.TEXTSPLIT(H15, ",")))) ) ) )} -> 8
A16: TIM17 | B16: DMA,1CH | C16: Port 4 / EXPANSION PORT | D16: =_xlfn.XLOOKUP(_xlfn.CONCAT($A16,"_",D$2),'UFBGA176+25 GPIOs'!$B$1:$B$133,'UFBGA176+25 GPIOs'!$A$1:$A$133,"NONE") -> PB9 | E16: =_xlfn.XLOOKUP(_xlfn.CONCAT($A16,"_",E$2),'UFBGA176+25 GPIOs'!$B$1:$B$133,'UFBGA176+25 GPIOs'!$A$1:$A$133,"NONE") -> NONE | F16: =_xlfn.XLOOKUP(_xlfn.CONCAT($A16,"_",F$2),'UFBGA176+25 GPIOs'!$B$1:$B$133,'UFBGA176+25 GPIOs'!$A$1:$A$133,"NONE") -> NONE | G16: =_xlfn.XLOOKUP(_xlfn.CONCAT($A16,"_",G$2),'UFBGA176+25 GPIOs'!$B$1:$B$133,'UFBGA176+25 GPIOs'!$A$1:$A$133,"NONE") -> NONE | H16: {=_xlfn.LET( _xlpm.joined, _xlfn.TEXTJOIN(",", TRUE, D16:G16), _xlpm.cleaned, _xlfn.TEXTJOIN("", TRUE, IF( (ISNUMBER(--MID(_xlpm.joined, _xlfn.SEQUENCE(LEN(_xlpm.joined)), 1))) + (MID(_xlpm.joined, _xlfn.SEQUENCE(LEN(_xlpm.joined)), 1) = ","), MID(_xlpm.joined, _xlfn.SEQUENCE(LEN(_xlpm.joined)), 1), "" ) ), IFERROR( _xlfn.TEXTJOIN(",", TRUE, _xlfn._xlws.FILTER(_xlfn.TEXTSPLIT(_xlpm.cleaned, ","), _xlfn.TEXTSPLIT(_xlpm.cleaned, ",")<>"") ), "" ) )} -> 9 | I16: {=IF( H16="", "", _xlfn.TEXTJOIN( ",", TRUE, _xlfn.SORTBY( _xlfn._xlws.FILTER(--TRIM(_xlfn.TEXTSPLIT(H16, ",")), ISNUMBER(--TRIM(_xlfn.TEXTSPLIT(H16, ",")))), --_xlfn._xlws.FILTER(--TRIM(_xlfn.TEXTSPLIT(H16, ",")), ISNUMBER(--TRIM(_xlfn.TEXTSPLIT(H16, ",")))) ) ) )} -> 9
A17: TIM23 | B17: Encoder,32bit,DMA,4CH | C17: Step/Dir/Step/Dir | D17: =_xlfn.XLOOKUP(_xlfn.CONCAT($A17,"_",D$2),'UFBGA176+25 GPIOs'!$B$1:$B$133,'UFBGA176+25 GPIOs'!$A$1:$A$133,"NONE") -> PF0 | E17: =_xlfn.XLOOKUP(_xlfn.CONCAT($A17,"_",E$2),'UFBGA176+25 GPIOs'!$B$1:$B$133,'UFBGA176+25 GPIOs'!$A$1:$A$133,"NONE") -> PF1 | F17: =_xlfn.XLOOKUP(_xlfn.CONCAT($A17,"_",F$2),'UFBGA176+25 GPIOs'!$B$1:$B$133,'UFBGA176+25 GPIOs'!$A$1:$A$133,"NONE") -> PF2 | G17: =_xlfn.XLOOKUP(_xlfn.CONCAT($A17,"_",G$2),'UFBGA176+25 GPIOs'!$B$1:$B$133,'UFBGA176+25 GPIOs'!$A$1:$A$133,"NONE") -> PF3 | H17: {=_xlfn.LET( _xlpm.joined, _xlfn.TEXTJOIN(",", TRUE, D17:G17), _xlpm.cleaned, _xlfn.TEXTJOIN("", TRUE, IF( (ISNUMBER(--MID(_xlpm.joined, _xlfn.SEQUENCE(LEN(_xlpm.joined)), 1))) + (MID(_xlpm.joined, _xlfn.SEQUENCE(LEN(_xlpm.joined)), 1) = ","), MID(_xlpm.joined, _xlfn.SEQUENCE(LEN(_xlpm.joined)), 1), "" ) ), IFERROR( _xlfn.TEXTJOIN(",", TRUE, _xlfn._xlws.FILTER(_xlfn.TEXTSPLIT(_xlpm.cleaned, ","), _xlfn.TEXTSPLIT(_xlpm.cleaned, ",")<>"") ), "" ) )} -> 0,1,2,3 | I17: {=IF( H17="", "", _xlfn.TEXTJOIN( ",", TRUE, _xlfn.SORTBY( _xlfn._xlws.FILTER(--TRIM(_xlfn.TEXTSPLIT(H17, ",")), ISNUMBER(--TRIM(_xlfn.TEXTSPLIT(H17, ",")))), --_xlfn._xlws.FILTER(--TRIM(_xlfn.TEXTSPLIT(H17, ",")), ISNUMBER(--TRIM(_xlfn.TEXTSPLIT(H17, ",")))) ) ) )} -> 0,1,2,3
A18: TIM24 | B18: Encoder,32bit,DMA,4CH | C18: Step/Dir/Step/Dir | D18: =_xlfn.XLOOKUP(_xlfn.CONCAT($A18,"_",D$2),'UFBGA176+25 GPIOs'!$B$1:$B$133,'UFBGA176+25 GPIOs'!$A$1:$A$133,"NONE") -> PF11 | E18: =_xlfn.XLOOKUP(_xlfn.CONCAT($A18,"_",E$2),'UFBGA176+25 GPIOs'!$B$1:$B$133,'UFBGA176+25 GPIOs'!$A$1:$A$133,"NONE") -> PF12 | F18: =_xlfn.XLOOKUP(_xlfn.CONCAT($A18,"_",F$2),'UFBGA176+25 GPIOs'!$B$1:$B$133,'UFBGA176+25 GPIOs'!$A$1:$A$133,"NONE") -> PF13 | G18: =_xlfn.XLOOKUP(_xlfn.CONCAT($A18,"_",G$2),'UFBGA176+25 GPIOs'!$B$1:$B$133,'UFBGA176+25 GPIOs'!$A$1:$A$133,"NONE") -> PF14 | H18: {=_xlfn.LET( _xlpm.joined, _xlfn.TEXTJOIN(",", TRUE, D18:G18), _xlpm.cleaned, _xlfn.TEXTJOIN("", TRUE, IF( (ISNUMBER(--MID(_xlpm.joined, _xlfn.SEQUENCE(LEN(_xlpm.joined)), 1))) + (MID(_xlpm.joined, _xlfn.SEQUENCE(LEN(_xlpm.joined)), 1) = ","), MID(_xlpm.joined, _xlfn.SEQUENCE(LEN(_xlpm.joined)), 1), "" ) ), IFERROR( _xlfn.TEXTJOIN(",", TRUE, _xlfn._xlws.FILTER(_xlfn.TEXTSPLIT(_xlpm.cleaned, ","), _xlfn.TEXTSPLIT(_xlpm.cleaned, ",")<>"") ), "" ) )} -> 11,12,13,14 | I18: {=IF( H18="", "", _xlfn.TEXTJOIN( ",", TRUE, _xlfn.SORTBY( _xlfn._xlws.FILTER(--TRIM(_xlfn.TEXTSPLIT(H18, ",")), ISNUMBER(--TRIM(_xlfn.TEXTSPLIT(H18, ",")))), --_xlfn._xlws.FILTER(--TRIM(_xlfn.TEXTSPLIT(H18, ",")), ISNUMBER(--TRIM(_xlfn.TEXTSPLIT(H18, ",")))) ) ) )} -> 11,12,13,14
A20: TIM1_ETR | C20: Port 1 / EXPANSION PORT | D20: =_xlfn.XLOOKUP($A20,'UFBGA176+25 GPIOs'!$B$1:$B$133,'UFBGA176+25 GPIOs'!$A$1:$A$133) -> PG5
A21: TIM8_ETR | C21: Port 3 / EXPANSION PORT | D21: =_xlfn.XLOOKUP($A21,'UFBGA176+25 GPIOs'!$B$1:$B$133,'UFBGA176+25 GPIOs'!$A$1:$A$133) -> PG8
D23: OUT1 | E23: OUT2 | F23: EXTI9
A24: DAC1 | C24: EXPANSION PORT | D24: =_xlfn.XLOOKUP(_xlfn.CONCAT($A24,"_",D$23),'UFBGA176+25 GPIOs'!$B$1:$B$133,'UFBGA176+25 GPIOs'!$A$1:$A$133) -> PA4 | E24: =_xlfn.XLOOKUP(_xlfn.CONCAT($A24,"_",E$23),'UFBGA176+25 GPIOs'!$B$1:$B$133,'UFBGA176+25 GPIOs'!$A$1:$A$133) -> #N/A | F24: =_xlfn.XLOOKUP(_xlfn.CONCAT($A24,"_",F$23),'UFBGA176+25 GPIOs'!$B$1:$B$133,'UFBGA176+25 GPIOs'!$A$1:$A$133) -> PH9
D26: SCK | E26: MISO | F26: MOSI | G26: NSS | H26: {=_xlfn.LET( _xlpm.joined, _xlfn.TEXTJOIN(",", TRUE, D26:G26), _xlpm.cleaned, _xlfn.TEXTJOIN("", TRUE, IF( (ISNUMBER(--MID(_xlpm.joined, _xlfn.SEQUENCE(LEN(_xlpm.joined)), 1))) + (MID(_xlpm.joined, _xlfn.SEQUENCE(LEN(_xlpm.joined)), 1) = ","), MID(_xlpm.joined, _xlfn.SEQUENCE(LEN(_xlpm.joined)), 1), "" ) ), IFERROR( _xlfn.TEXTJOIN(",", TRUE, _xlfn._xlws.FILTER(_xlfn.TEXTSPLIT(_xlpm.cleaned, ","), _xlfn.TEXTSPLIT(_xlpm.cleaned, ",")<>"") ), "" ) )} | I26: {=IF( H26="", "", _xlfn.TEXTJOIN( ",", TRUE, _xlfn.SORTBY( _xlfn._xlws.FILTER(--TRIM(_xlfn.TEXTSPLIT(H26, ",")), ISNUMBER(--TRIM(_xlfn.TEXTSPLIT(H26, ",")))), --_xlfn._xlws.FILTER(--TRIM(_xlfn.TEXTSPLIT(H26, ",")), ISNUMBER(--TRIM(_xlfn.TEXTSPLIT(H26, ",")))) ) ) )}
A27: SPI1 | C27: EXPANSION PORT | D27: =_xlfn.XLOOKUP(_xlfn.CONCAT($A27,"_",D$26),'UFBGA176+25 GPIOs'!$B$1:$B$133,'UFBGA176+25 GPIOs'!$A$1:$A$133) -> PA5 | E27: =_xlfn.XLOOKUP(_xlfn.CONCAT($A27,"_",E$26),'UFBGA176+25 GPIOs'!$B$1:$B$133,'UFBGA176+25 GPIOs'!$A$1:$A$133) -> PB4(NJTRST) | F27: =_xlfn.XLOOKUP(_xlfn.CONCAT($A27,"_",F$26),'UFBGA176+25 GPIOs'!$B$1:$B$133,'UFBGA176+25 GPIOs'!$A$1:$A$133) -> PD7 | G27: =_xlfn.XLOOKUP(_xlfn.CONCAT($A27,"_",G$26),'UFBGA176+25 GPIOs'!$B$1:$B$133,'UFBGA176+25 GPIOs'!$A$1:$A$133) -> #N/A | H27: {=_xlfn.LET( _xlpm.joined, _xlfn.TEXTJOIN(",", TRUE, D27:G27), _xlpm.cleaned, _xlfn.TEXTJOIN("", TRUE, IF( (ISNUMBER(--MID(_xlpm.joined, _xlfn.SEQUENCE(LEN(_xlpm.joined)), 1))) + (MID(_xlpm.joined, _xlfn.SEQUENCE(LEN(_xlpm.joined)), 1) = ","), MID(_xlpm.joined, _xlfn.SEQUENCE(LEN(_xlpm.joined)), 1), "" ) ), IFERROR( _xlfn.TEXTJOIN(",", TRUE, _xlfn._xlws.FILTER(_xlfn.TEXTSPLIT(_xlpm.cleaned, ","), _xlfn.TEXTSPLIT(_xlpm.cleaned, ",")<>"") ), "" ) )} | I27: {=IF( H27="", "", _xlfn.TEXTJOIN( ",", TRUE, _xlfn.SORTBY( _xlfn._xlws.FILTER(--TRIM(_xlfn.TEXTSPLIT(H27, ",")), ISNUMBER(--TRIM(_xlfn.TEXTSPLIT(H27, ",")))), --_xlfn._xlws.FILTER(--TRIM(_xlfn.TEXTSPLIT(H27, ",")), ISNUMBER(--TRIM(_xlfn.TEXTSPLIT(H27, ",")))) ) ) )}
A28: SPI2 | C28: Port 1 | D28: =_xlfn.XLOOKUP(_xlfn.CONCAT($A28,"_",D$26),'UFBGA176+25 GPIOs'!$B$1:$B$133,'UFBGA176+25 GPIOs'!$A$1:$A$133) -> PD3 | E28: =_xlfn.XLOOKUP(_xlfn.CONCAT($A28,"_",E$26),'UFBGA176+25 GPIOs'!$B$1:$B$133,'UFBGA176+25 GPIOs'!$A$1:$A$133) -> PB14 | F28: =_xlfn.XLOOKUP(_xlfn.CONCAT($A28,"_",F$26),'UFBGA176+25 GPIOs'!$B$1:$B$133,'UFBGA176+25 GPIOs'!$A$1:$A$133) -> PB15 | G28: =_xlfn.XLOOKUP(_xlfn.CONCAT($A28,"_",G$26),'UFBGA176+25 GPIOs'!$B$1:$B$133,'UFBGA176+25 GPIOs'!$A$1:$A$133) -> PB12 | H28: {=_xlfn.LET( _xlpm.joined, _xlfn.TEXTJOIN(",", TRUE, D28:G28), _xlpm.cleaned, _xlfn.TEXTJOIN("", TRUE, IF( (ISNUMBER(--MID(_xlpm.joined, _xlfn.SEQUENCE(LEN(_xlpm.joined)), 1))) + (MID(_xlpm.joined, _xlfn.SEQUENCE(LEN(_xlpm.joined)), 1) = ","), MID(_xlpm.joined, _xlfn.SEQUENCE(LEN(_xlpm.joined)), 1), "" ) ), IFERROR( _xlfn.TEXTJOIN(",", TRUE, _xlfn._xlws.FILTER(_xlfn.TEXTSPLIT(_xlpm.cleaned, ","), _xlfn.TEXTSPLIT(_xlpm.cleaned, ",")<>"") ), "" ) )} -> 3,14,15,12 | I28: {=IF( H28="", "", _xlfn.TEXTJOIN( ",", TRUE, _xlfn.SORTBY( _xlfn._xlws.FILTER(--TRIM(_xlfn.TEXTSPLIT(H28, ",")), ISNUMBER(--TRIM(_xlfn.TEXTSPLIT(H28, ",")))), --_xlfn._xlws.FILTER(--TRIM(_xlfn.TEXTSPLIT(H28, ",")), ISNUMBER(--TRIM(_xlfn.TEXTSPLIT(H28, ",")))) ) ) )} -> 3,12,14,15
A29: SPI3 | C29: Port 2 | D29: =_xlfn.XLOOKUP(_xlfn.CONCAT($A29,"_",D$26),'UFBGA176+25 GPIOs'!$B$1:$B$133,'UFBGA176+25 GPIOs'!$A$1:$A$133) -> PC10 | E29: =_xlfn.XLOOKUP(_xlfn.CONCAT($A29,"_",E$26),'UFBGA176+25 GPIOs'!$B$1:$B$133,'UFBGA176+25 GPIOs'!$A$1:$A$133) -> PC11 | F29: =_xlfn.XLOOKUP(_xlfn.CONCAT($A29,"_",F$26),'UFBGA176+25 GPIOs'!$B$1:$B$133,'UFBGA176+25 GPIOs'!$A$1:$A$133) -> PB2 | G29: =_xlfn.XLOOKUP(_xlfn.CONCAT($A29,"_",G$26),'UFBGA176+25 GPIOs'!$B$1:$B$133,'UFBGA176+25 GPIOs'!$A$1:$A$133) -> PA15(JTDI) | H29: {=_xlfn.LET( _xlpm.joined, _xlfn.TEXTJOIN(",", TRUE, D29:G29), _xlpm.cleaned, _xlfn.TEXTJOIN("", TRUE, IF( (ISNUMBER(--MID(_xlpm.joined, _xlfn.SEQUENCE(LEN(_xlpm.joined)), 1))) + (MID(_xlpm.joined, _xlfn.SEQUENCE(LEN(_xlpm.joined)), 1) = ","), MID(_xlpm.joined, _xlfn.SEQUENCE(LEN(_xlpm.joined)), 1), "" ) ), IFERROR( _xlfn.TEXTJOIN(",", TRUE, _xlfn._xlws.FILTER(_xlfn.TEXTSPLIT(_xlpm.cleaned, ","), _xlfn.TEXTSPLIT(_xlpm.cleaned, ",")<>"") ), "" ) )} -> 10,11,2,15 | I29: {=IF( H29="", "", _xlfn.TEXTJOIN( ",", TRUE, _xlfn.SORTBY( _xlfn._xlws.FILTER(--TRIM(_xlfn.TEXTSPLIT(H29, ",")), ISNUMBER(--TRIM(_xlfn.TEXTSPLIT(H29, ",")))), --_xlfn._xlws.FILTER(--TRIM(_xlfn.TEXTSPLIT(H29, ",")), ISNUMBER(--TRIM(_xlfn.TEXTSPLIT(H29, ",")))) ) ) )} -> 2,10,11,15
A30: SPI4 | C30: Port 3 | D30: =_xlfn.XLOOKUP(_xlfn.CONCAT($A30,"_",D$26),'UFBGA176+25 GPIOs'!$B$1:$B$133,'UFBGA176+25 GPIOs'!$A$1:$A$133) -> PE12 | E30: =_xlfn.XLOOKUP(_xlfn.CONCAT($A30,"_",E$26),'UFBGA176+25 GPIOs'!$B$1:$B$133,'UFBGA176+25 GPIOs'!$A$1:$A$133) -> PE5 | F30: =_xlfn.XLOOKUP(_xlfn.CONCAT($A30,"_",F$26),'UFBGA176+25 GPIOs'!$B$1:$B$133,'UFBGA176+25 GPIOs'!$A$1:$A$133) -> PE6 | G30: =_xlfn.XLOOKUP(_xlfn.CONCAT($A30,"_",G$26),'UFBGA176+25 GPIOs'!$B$1:$B$133,'UFBGA176+25 GPIOs'!$A$1:$A$133) -> PE4 | H30: {=_xlfn.LET( _xlpm.joined, _xlfn.TEXTJOIN(",", TRUE, D30:G30), _xlpm.cleaned, _xlfn.TEXTJOIN("", TRUE, IF( (ISNUMBER(--MID(_xlpm.joined, _xlfn.SEQUENCE(LEN(_xlpm.joined)), 1))) + (MID(_xlpm.joined, _xlfn.SEQUENCE(LEN(_xlpm.joined)), 1) = ","), MID(_xlpm.joined, _xlfn.SEQUENCE(LEN(_xlpm.joined)), 1), "" ) ), IFERROR( _xlfn.TEXTJOIN(",", TRUE, _xlfn._xlws.FILTER(_xlfn.TEXTSPLIT(_xlpm.cleaned, ","), _xlfn.TEXTSPLIT(_xlpm.cleaned, ",")<>"") ), "" ) )} -> 12,5,6,4 | I30: {=IF( H30="", "", _xlfn.TEXTJOIN( ",", TRUE, _xlfn.SORTBY( _xlfn._xlws.FILTER(--TRIM(_xlfn.TEXTSPLIT(H30, ",")), ISNUMBER(--TRIM(_xlfn.TEXTSPLIT(H30, ",")))), --_xlfn._xlws.FILTER(--TRIM(_xlfn.TEXTSPLIT(H30, ",")), ISNUMBER(--TRIM(_xlfn.TEXTSPLIT(H30, ",")))) ) ) )} -> 4,5,6,12
A31: SPI5 | C31: Port 4 | D31: =_xlfn.XLOOKUP(_xlfn.CONCAT($A31,"_",D$26),'UFBGA176+25 GPIOs'!$B$1:$B$133,'UFBGA176+25 GPIOs'!$A$1:$A$133) -> PH6 | E31: =_xlfn.XLOOKUP(_xlfn.CONCAT($A31,"_",E$26),'UFBGA176+25 GPIOs'!$B$1:$B$133,'UFBGA176+25 GPIOs'!$A$1:$A$133) -> PF8 | F31: =_xlfn.XLOOKUP(_xlfn.CONCAT($A31,"_",F$26),'UFBGA176+25 GPIOs'!$B$1:$B$133,'UFBGA176+25 GPIOs'!$A$1:$A$133) -> PF9 | G31: =_xlfn.XLOOKUP(_xlfn.CONCAT($A31,"_",G$26),'UFBGA176+25 GPIOs'!$B$1:$B$133,'UFBGA176+25 GPIOs'!$A$1:$A$133) -> PF6 | H31: {=_xlfn.LET( _xlpm.joined, _xlfn.TEXTJOIN(",", TRUE, D31:G31), _xlpm.cleaned, _xlfn.TEXTJOIN("", TRUE, IF( (ISNUMBER(--MID(_xlpm.joined, _xlfn.SEQUENCE(LEN(_xlpm.joined)), 1))) + (MID(_xlpm.joined, _xlfn.SEQUENCE(LEN(_xlpm.joined)), 1) = ","), MID(_xlpm.joined, _xlfn.SEQUENCE(LEN(_xlpm.joined)), 1), "" ) ), IFERROR( _xlfn.TEXTJOIN(",", TRUE, _xlfn._xlws.FILTER(_xlfn.TEXTSPLIT(_xlpm.cleaned, ","), _xlfn.TEXTSPLIT(_xlpm.cleaned, ",")<>"") ), "" ) )} -> 6,8,9,6 | I31: {=IF( H31="", "", _xlfn.TEXTJOIN( ",", TRUE, _xlfn.SORTBY( _xlfn._xlws.FILTER(--TRIM(_xlfn.TEXTSPLIT(H31, ",")), ISNUMBER(--TRIM(_xlfn.TEXTSPLIT(H31, ",")))), --_xlfn._xlws.FILTER(--TRIM(_xlfn.TEXTSPLIT(H31, ",")), ISNUMBER(--TRIM(_xlfn.TEXTSPLIT(H31, ",")))) ) ) )} -> 6,6,8,9
A32: SPI6 | D32: =_xlfn.XLOOKUP(_xlfn.CONCAT($A32,"_",D$26),'UFBGA176+25 GPIOs'!$B$1:$B$133,'UFBGA176+25 GPIOs'!$A$1:$A$133) -> #N/A | E32: =_xlfn.XLOOKUP(_xlfn.CONCAT($A32,"_",E$26),'UFBGA176+25 GPIOs'!$B$1:$B$133,'UFBGA176+25 GPIOs'!$A$1:$A$133) -> #N/A | F32: =_xlfn.XLOOKUP(_xlfn.CONCAT($A32,"_",F$26),'UFBGA176+25 GPIOs'!$B$1:$B$133,'UFBGA176+25 GPIOs'!$A$1:$A$133) -> #N/A | G32: =_xlfn.XLOOKUP(_xlfn.CONCAT($A32,"_",G$26),'UFBGA176+25 GPIOs'!$B$1:$B$133,'UFBGA176+25 GPIOs'!$A$1:$A$133) -> #N/A | H32: {=_xlfn.LET( _xlpm.joined, _xlfn.TEXTJOIN(",", TRUE, D32:G32), _xlpm.cleaned, _xlfn.TEXTJOIN("", TRUE, IF( (ISNUMBER(--MID(_xlpm.joined, _xlfn.SEQUENCE(LEN(_xlpm.joined)), 1))) + (MID(_xlpm.joined, _xlfn.SEQUENCE(LEN(_xlpm.joined)), 1) = ","), MID(_xlpm.joined, _xlfn.SEQUENCE(LEN(_xlpm.joined)), 1), "" ) ), IFERROR( _xlfn.TEXTJOIN(",", TRUE, _xlfn._xlws.FILTER(_xlfn.TEXTSPLIT(_xlpm.cleaned, ","), _xlfn.TEXTSPLIT(_xlpm.cleaned, ",")<>"") ), "" ) )} | I32: {=IF( H32="", "", _xlfn.TEXTJOIN( ",", TRUE, _xlfn.SORTBY( _xlfn._xlws.FILTER(--TRIM(_xlfn.TEXTSPLIT(H32, ",")), ISNUMBER(--TRIM(_xlfn.TEXTSPLIT(H32, ",")))), --_xlfn._xlws.FILTER(--TRIM(_xlfn.TEXTSPLIT(H32, ",")), ISNUMBER(--TRIM(_xlfn.TEXTSPLIT(H32, ",")))) ) ) )}
A34: Need 2x SW NSS for either SPI1 or SPI6
A35: SPI1_NSS_SW_1 | C35: EXPANSION PORT | D35: =_xlfn.XLOOKUP($A35,'UFBGA176+25 GPIOs'!$H$1:$H$133,'UFBGA176+25 GPIOs'!$A$1:$A$133) -> PD10
A36: SPI1_NSS_SW_2 | C36: EXPANSION PORT | D36: =_xlfn.XLOOKUP($A36,'UFBGA176+25 GPIOs'!$H$1:$H$133,'UFBGA176+25 GPIOs'!$A$1:$A$133) -> PF5
A37: SPI2_NSS_2 | D37: =_xlfn.XLOOKUP($A37,'UFBGA176+25 GPIOs'!$H$1:$H$133,'UFBGA176+25 GPIOs'!$A$1:$A$133) -> PG3
A38: SPI3_NSS_2 | D38: =_xlfn.XLOOKUP($A38,'UFBGA176+25 GPIOs'!$H$1:$H$133,'UFBGA176+25 GPIOs'!$A$1:$A$133) -> PG2
A39: SPI4_NSS_2 | D39: =_xlfn.XLOOKUP($A39,'UFBGA176+25 GPIOs'!$H$1:$H$133,'UFBGA176+25 GPIOs'!$A$1:$A$133) -> PG7
A40: SPI5_NSS_2 | D40: =_xlfn.XLOOKUP($A40,'UFBGA176+25 GPIOs'!$H$1:$H$133,'UFBGA176+25 GPIOs'!$A$1:$A$133) -> PG15
A41: SPI6_NSS_SW_1 | C41: WIFI | D41: =_xlfn.XLOOKUP($A41,'UFBGA176+25 GPIOs'!$H$1:$H$133,'UFBGA176+25 GPIOs'!$A$1:$A$133) -> #N/A
A42: SPI6_NSS_SW_2 | C42: EXPANSION PORT | D42: =_xlfn.XLOOKUP($A42,'UFBGA176+25 GPIOs'!$H$1:$H$133,'UFBGA176+25 GPIOs'!$A$1:$A$133) -> #N/A
A44: Used GPIO ports for SPI | D44: {=_xlfn.TEXTJOIN(",", TRUE, _xlfn._xlws.SORT(_xlfn.UNIQUE(MID(_xlfn._xlws.FILTER(_xlfn.TOCOL(D28:G31), LEFT(_xlfn.TOCOL(D28:G31),1)="P"), 2, 1))))} -> A,B,C,D,E,F,H
D46: P1_DQS | E46: P1_NCS | F46: P1_CLK | G46: P1_NCLK | H46: P1_IO0 | I46: P1_IO1 | J46: P1_IO2 | K46: P1_IO3
...

Sheet UFBGA176+25 GPIOs
A1: Pin | B1: Signal | C1: GPIO Output level | D1: Mode | E1: Pu/Pd | F1: Speed | G1: Fast mode | H1: Label | I1: Modified
A2: PA0 | B2: TIM2_CH1 | C2: n/a | D2: Alternate Function Push Pull | E2: No pull-up and no pull-down | F2: Low | G2: n/a | I2: FALSE
A3: PA1 | B3: ETH_REF_CLK | C3: n/a | D3: Alternate Function Push Pull | E3: No pull-up and no pull-down | F3: High | G3: n/a | I3: FALSE
A4: PA1_C | B4: ADC1_INP1 | C4: n/a | D4: Analog mode | E4: No pull-up and no pull-down | F4: n/a | G4: n/a | H4: ANALOG_IN_2 | I4: TRUE
A5: PA2 | B5: ETH_MDIO | C5: n/a | D5: Alternate Function Push Pull | E5: No pull-up and no pull-down | F5: High | G5: n/a | I5: FALSE
A6: PA3 | B6: TIM5_CH4 | C6: n/a | D6: Alternate Function Push Pull | E6: No pull-up and no pull-down | F6: Low | G6: n/a | I6: FALSE
A7: PA4 | B7: DAC1_OUT1 | C7: n/a | D7: Analog mode | E7: No pull-up and no pull-down | F7: n/a | G7: n/a | I7: FALSE
A8: PA5 | B8: SPI1_SCK | C8: n/a | D8: Alternate Function Push Pull | E8: No pull-up and no pull-down | F8: Low | G8: n/a | I8: FALSE
A9: PA6 | B9: TIM3_CH1 | C9: n/a | D9: Alternate Function Push Pull | E9: No pull-up and no pull-down | F9: Low | G9: n/a | I9: FALSE
A10: PA7 | B10: ETH_CRS_DV | C10: n/a | D10: Alternate Function Push Pull | E10: No pull-up and no pull-down | F10: High | G10: n/a | I10: FALSE
A11: PA8 | B11: RCC_MCO_1 | C11: n/a | D11: Alternate Function Push Pull | E11: No pull-up and no pull-down | F11: Low | G11: n/a | I11: FALSE
A12: PA9 | B12: USART1_TX | C12: n/a | D12: Alternate Function Push Pull | E12: No pull-up and no pull-down | F12: Low | G12: n/a | I12: FALSE
A13: PA10 | B13: USART1_RX | C13: n/a | D13: Alternate Function Push Pull | E13: No pull-up and no pull-down | F13: Low | G13: n/a | I13: FALSE
A14: PA11 | B14: USB_OTG_HS_DM | C14: n/a | D14: n/a | E14: n/a | F14: n/a | G14: n/a | I14: FALSE
A15: PA12 | B15: USB_OTG_HS_DP | C15: n/a | D15: n/a | E15: n/a | F15: n/a | G15: n/a | I15: FALSE
A16: PA13(JTMS/SWDIO) | B16: DEBUG_JTMS-SWDIO | C16: n/a | D16: n/a | E16: n/a | F16: n/a | G16: n/a | I16: FALSE
... A18: PA15(JTDI) | B18: SPI3_NSS | C18: n/a | D18: Alternate Function Push Pull | E18: No pull-up and no pull-down | F18: Low | G18: n/a | I18: FALSE
A19: PA0_C | B19: ADC1_INP0 | C19: n/a | D19: Analog mode | E19: No pull-up and no pull-down | F19: n/a | G19: n/a | H19: ANALOG_IN_1 | I19: TRUE
A20: PB0 | B20: TIM3_CH3 | C20: n/a | D20: Alternate Function Push Pull | E20: No pull-up and no pull-down | F20: Low | G20: n/a | I20: FALSE
A21: PB1 | B21: TIM3_CH4 | C21: n/a | D21: Alternate Function Push Pull | E21: No pull-up and no pull-down | F21: Low | G21: n/a | I21: FALSE
A22: PB2 | B22: SPI3_MOSI | C22: n/a | D22: Alternate Function Push Pull | E22: No pull-up and no pull-down | F22: Low | G22: n/a | I22: FALSE
A23: PB3(JTDO/TRACESWO) | B23: TIM2_CH2 | C23: n/a | D23: Alternate Function Push Pull | E23: No pull-up and no pull-down | F23: Low | G23: n/a | I23: FALSE
A24: PB4(NJTRST) | B24: SPI1_MISO | C24: n/a | D24: Alternate Function Push Pull | E24: No pull-up and no pull-down | F24: Low | G24: n/a | I24: FALSE
A25: PB5 | B25: TIM3_CH2 | C25: n/a | D25: Alternate Function Push Pull | E25: No pull-up and no pull-down | F25: Low | G25: n/a | I25: FALSE
A26: PB6 | B26: TIM4_CH1 | C26: n/a | D26: Alternate Function Push Pull | E26: No pull-up and no pull-down | F26: Low | G26: Disable | I26: FALSE
A27: PB7 | B27: TIM4_CH2 | C27: n/a | D27: Alternate Function Push Pull | E27: No pull-up and no pull-down | F27: Low | G27: Disable | I27: FALSE
A28: PB8 | B28: TIM16_CH1 | C28: n/a | D28: Alternate Function Push Pull | E28: No pull-up and no pull-down | F28: Low | G28: Disable | H28: PWM_OUT_1 | I28: TRUE
A29: PB9 | B29: TIM17_CH1 | C29: n/a | D29: Alternate Function Push Pull | E29: No pull-up and no pull-down | F29: Low | G29: Disable | H29: PWM_OUT_2 | I29: TRUE
A30: PB10 | B30: TIM2_CH3 | C30: n/a | D30: Alternate Function Push Pull | E30: No pull-up and no pull-down | F30: Low | G30: n/a | I30: FALSE
A31: PB11 | B31: TIM2_CH4 | C31: n/a | D31: Alternate Function Push Pull | E31: No pull-up and no pull-down | F31: Low | G31: n/a | I31: FALSE
A32: PB12 | B32: SPI2_NSS | C32: n/a | D32: Alternate Function Push Pull | E32: No pull-up and no pull-down | F32: Low | G32: n/a | I32: FALSE
A33: PB13 | B33: ETH_TXD1 | C33: n/a | D33: Alternate Function Push Pull | E33: No pull-up and no pull-down | F33: High | G33: n/a | I33: FALSE
A34: PB14 | B34: SPI2_MISO | C34: n/a | D34: Alternate Function Push Pull | E34: No pull-up and no pull-down | F34: Low | G34: n/a | I34: FALSE
A35: PB15 | B35: SPI2_MOSI | C35: n/a | D35: Alternate Function Push Pull | E35: No pull-up and no pull-down | F35: Low | G35: n/a | I35: FALSE
A36: PC0 | B36: ADC3_INP10 | C36: n/a | D36: Analog mode | E36: No pull-up and no pull-down | F36: n/a | G36: n/a | H36: ANALOG_IN_5 | I36: TRUE
A37: PC1 | B37: ETH_MDC | C37: n/a | D37: Alternate Function Push Pull | E37: No pull-up and no pull-down | F37: High | G37: n/a | I37: FALSE
A38: PC2 | B38: OCTOSPIM_P1_IO2 | C38: n/a | D38: Alternate Function Push Pull | E38: No pull-up and no pull-down | F38: Very High | G38: n/a | I38: FALSE
A39: PC2_C | B39: ADC3_INP0 | C39: n/a | D39: Analog mode | E39: No pull-up and no pull-down | F39: n/a | G39: n/a | H39: ANALOG_IN_3 | I39: TRUE
A40: PC3 | B40: OCTOSPIM_P1_IO6 | C40: n/a | D40: Alternate Function Push Pull | E40: No pull-up and no pull-down | F40: Very High | G40: n/a | I40: FALSE
A41: PC3_C | B41: ADC3_INP1 | C41: n/a | D41: Analog mode | E41: No pull-up and no pull-down | F41: n/a | G41: n/a | H41: ANALOG_IN_4 | I41: TRUE
...

Sheet PORT_PINS
A1: References
A2: PCI-E Connector pinout, with handy card diagrams | E2: https://pinoutguide.com/Slots/pci_express_pinout.shtml
A3: Wikipedia page | E3: https://en.wikipedia.org/wiki/PCI_Express
A5: PRESENT_1 should be routed to PRESENT_2 on the card itself - to check for proper insertion before using the card.
A6: Each card has SWO/SWD/RESET signals for programming via the FPGA, or for 3x GPIOs
A8: A=Solder(Bottom) B=Component Side(Top)
A11: Expansion port pins | B11: Signal | C11: Offset | D11: Side | E11: Routed to | F11: Notes | G11: Usage 1 | H11: Usage 2 | I11: Usage 3 | J11: On FPGA signal list
A12: 1 | B12: PRESENT_1 | C12: 1 | D12: A | E12: FPGA | J12: YES
A13: 2 | B13: 24v | C13: 1 | D13: B | F13: Main power pins | J13: N/A
A14: 3 | B14: 24v | C14: =C12+1 -> 2 | D14: A | F14: Main power pins | J14: N/A
A15: 4 | B15: 24v | C15: =C13+1 -> 2 | D15: B | F15: Main power pins | J15: N/A
A16: 5 | B16: 24v | C16: =C14+1 -> 3 | D16: A | F16: Main power pins | J16: N/A
A17: 6 | B17: 24v | C17: =C15+1 -> 3 | D17: B | F17: Main power pins | J17: N/A
A18: 7 | B18: GND | C18: =C16+1 -> 4 | D18: A | J18: N/A
A19: 8 | B19: GND | C19: =C17+1 -> 4 | D19: B | J19: N/A
A20: 9 | B20: USB+ | C20: =C18+1 -> 5 | D20: A | E20: USB_HUB | F20: Differential pair | J20: N/A
A21: 10 | B21: SWO | C21: =C19+1 -> 5 | D21: B | E21: FPGA | G21: Programming | H21: GPIO | J21: YES
A22: 11 | B22: USB- | C22: =C20+1 -> 6 | D22: A | E22: USB_HUB | F22: Differential pair | J22: N/A
A23: 12 | B23: SWD | C23: =C21+1 -> 6 | D23: B | E23: FPGA | G23: Programming | H23: GPIO | J23: YES
A24: 13 | B24: CAN+ | C24: =C22+1 -> 7 | D24: A | E24: CAN_TRANCEIVER | F24: Differential pair | J24: N/A
A25: 14 | B25: GND | C25: =C23+1 -> 7 | D25: B | J25: N/A
A26: 15 | B26: CAN- | C26: =C24+1 -> 8 | D26: A | E26: CAN_TRANCEIVER | F26: Differential pair | J26: N/A
A27: 16 | B27: 3v3 | C27: =C25+1 -> 8 | D27: B | J27: N/A
A28: 17 | B28: 3v3 | C28: =C26+1 -> 9 | D28: A | J28: N/A
A29: 18 | B29: PROG_RESET | C29: =C27+1 -> 9 | D29: B | E29: FPGA, for NRESET on any MCU on the card | G29: Programming | H29: GPIO | J29: YES
A30: 19 | B30: 3v3 | C30: =C28+1 -> 10 | D30: A | J30: N/A
A31: 20 | B31: 3v3 | C31: =C29+1 -> 10 | D31: B | J31: N/A
A32: 21 | B32: MCU_NRESET | C32: =C30+1 -> 11 | D32: A | E32: MCU | J32: N/A
A33: 22 | B33: WAKE | C33: =C31+1 -> 11 | D33: B | E33: FPGA | G33: MCU on card to signal FPGA | J33: YES
A34: 23 | B34: GND | C34: =C32+1 -> 12 | D34: A | J34: N/A
A35: 24 | B35: CLK | C35: =C33+1 -> 12 | D35: B | E35: FPGA | G35: FPGA generated clock (per port) | J35: N/A
A36: 25 | B36: ANALOG_MUX_IN_1 | C36: =C34+1 -> 13 | D36: A | E36: MUX_CH0 | J36: N/A
A37: 26 | B37: ANALOG_MUX_IN_2 | C37: =C35+1 -> 13 | D37: B | E37: MUX_CH1 | J37: N/A
A38: 27 | B38: ETR/PWM | C38: =C36+1 -> 14 | D38: A | E38: MCU | F38: TIM1/TIM8_ETR on port 1/3, PWM via TIM16_CH1/TIM17_CH1 on port 2/4 | J38: N/A
A39: 28 | B39: INT | C39: =C37+1 -> 14 | D39: B | E39: FPGA | G39: Interrupt signal | J39: N/A
A40: 29 | B40: I2C_SCL | C40: =C38+1 -> 15 | D40: A | E40: MCU, via I2C 4:1 I2C Bus Switch | G40: Small I2C flash for identification | H40: Other I2C devices | J40: N/A
A41: 30 | B41: GND | C41: =C39+1 -> 15 | D41: B | J41: N/A
A42: 31 | B42: I2C_SDA | C42: =C40+1 -> 16 | D42: A | E42: MCU, via I2C 4:1 I2C Bus Switch | G42: Small I2C flash for identification | H42: Other I2C devices | J42: N/A
A43: 32 | B43: SPI_HW_NSS_1 | C43: =C41+1 -> 16 | D43: B | E43: MCU | G43: SPI | H43: GPIO | J43: N/A
A44: 33 | B44: GND | C44: =C42+1 -> 17 | D44: A | J44: N/A
...

Sheet FPGA_SIGNALS
A1: Signal # | B1: FPGA signals | C1: Routed To | D1: Port | E1: Function | F1: Column1 | G1: Column2 | H1: Column3
A2: 1 | B2: =_xlfn.CONCAT(C2,"_",D2) -> WAKE_PORT1 | C2: WAKE | D2: PORT1 | E2: Peripheral Interrupt Signal
A3: 2 | B3: =_xlfn.CONCAT(C3,"_",D3) -> WAKE_PORT2 | C3: WAKE | D3: PORT2 | E3: Peripheral Interrupt Signal
A4: 3 | B4: =_xlfn.CONCAT(C4,"_",D4) -> WAKE_PORT3 | C4: WAKE | D4: PORT3 | E4: Peripheral Interrupt Signal
A5: 4 | B5: =_xlfn.CONCAT(C5,"_",D5) -> WAKE_PORT4 | C5: WAKE | D5: PORT4 | E5: Peripheral Interrupt Signal
A6: 5 | B6: =_xlfn.CONCAT(C6,"_",D6) -> ENCODER1_A_PORT1 | C6: ENCODER1_A | D6: PORT1 | E6: Encoder 1
A7: 6 | B7: =_xlfn.CONCAT(C7,"_",D7) -> ENCODER1_B_PORT1 | C7: ENCODER1_B | D7: PORT1 | E7: Encoder 1
A8: 7 | B8: =_xlfn.CONCAT(C8,"_",D8) -> ENCODER1_N_PORT1 | C8: ENCODER1_N | D8: PORT1 | E8: Encoder 1
A9: 8 | B9: =_xlfn.CONCAT(C9,"_",D9) -> ENCODER2_A_PORT1 | C9: ENCODER2_A | D9: PORT1 | E9: Encoder 2
A10: 9 | B10: =_xlfn.CONCAT(C10,"_",D10) -> ENCODER2_B_PORT1 | C10: ENCODER2_B | D10: PORT1 | E10: Encoder 2
A11: 10 | B11: =_xlfn.CONCAT(C11,"_",D11) -> ENCODER2_N_PORT1 | C11: ENCODER2_N | D11: PORT1 | E11: Encoder 2
A12: 11 | B12: =_xlfn.CONCAT(C12,"_",D12) -> ENCODER1_A_PORT2 | C12: ENCODER1_A | D12: PORT2 | E12: Encoder 3
A13: 12 | B13: =_xlfn.CONCAT(C13,"_",D13) -> ENCODER1_B_PORT2 | C13: ENCODER1_B | D13: PORT2 | E13: Encoder 3
... A29: 28 | B29: =_xlfn.CONCAT(C29,"_",D29) -> ENCODER2_N_PORT4 | C29: ENCODER2_N | D29: PORT4 | E29: Encoder 8
A30: 29 | B30: =_xlfn.CONCAT(C30,"_",D30) -> TIMER1_CH1_IN_PORT1 | C30: TIMER1_CH1_IN | D30: PORT1 | E30: GPIO Mux | F30: MUX Input 0
A31: 30 | B31: =_xlfn.CONCAT(C31,"_",D31) -> TIMER1_CH1_OUT_PORT1 | C31: TIMER1_CH1_OUT | D31: PORT1 | E31: GPIO Mux | F31: MUX Output 0
A32: 31 | B32: =_xlfn.CONCAT(C32,"_",D32) -> TIMER1_CH2_IN_PORT1 | C32: TIMER1_CH2_IN | D32: PORT1 | E32: GPIO Mux | F32: MUX Input 1
A33: 32 | B33: =_xlfn.CONCAT(C33,"_",D33) -> TIMER1_CH2_OUT_PORT1 | C33: TIMER1_CH2_OUT | D33: PORT1 | E33: GPIO Mux | F33: MUX Output 1
A34: 33 | B34: =_xlfn.CONCAT(C34,"_",D34) -> TIMER1_CH2_IN_PORT1 | C34: TIMER1_CH2_IN | D34: PORT1 | E34: GPIO Mux | F34: MUX Input 2
A35: 34 | B35: =_xlfn.CONCAT(C35,"_",D35) -> TIMER1_CH2_OUT_PORT1 | C35: TIMER1_CH2_OUT | D35: PORT1 | E35: GPIO Mux | F35: MUX Output 2
A36: 35 | B36: =_xlfn.CONCAT(C36,"_",D36) -> TIMER1_CH2_IN_PORT1 | C36: TIMER1_CH2_IN | D36: PORT1 | E36: GPIO Mux | F36: MUX Input 3
A37: 36 | B37: =_xlfn.CONCAT(C37,"_",D37) -> TIMER1_CH2_OUT_PORT1 | C37: TIMER1_CH2_OUT | D37: PORT1 | E37: GPIO Mux | F37: MUX Output 3
A38: 37 | B38: =_xlfn.CONCAT(C38,"_",D38) -> TIMER2_CH1_IN_PORT1 | C38: TIMER2_CH1_IN | D38: PORT1 | E38: GPIO Mux | F38: MUX Input 4
A39: 38 | B39: =_xlfn.CONCAT(C39,"_",D39) -> TIMER2_CH1_OUT_PORT1 | C39: TIMER2_CH1_OUT | D39: PORT1 | E39: GPIO Mux | F39: MUX Output 4
A40: 39 | B40: =_xlfn.CONCAT(C40,"_",D40) -> TIMER2_CH2_IN_PORT1 | C40: TIMER2_CH2_IN | D40: PORT1 | E40: GPIO Mux | F40: MUX Input 5
A41: 40 | B41: =_xlfn.CONCAT(C41,"_",D41) -> TIMER2_CH2_OUT_PORT1 | C41: TIMER2_CH2_OUT | D41: PORT1 | E41: GPIO Mux | F41: MUX Output 5
... A93: 92 | B93: =_xlfn.CONCAT(C93,"_",D93) -> TIMER2_CH2_OUT_PORT4 | C93: TIMER2_CH2_OUT | D93: PORT4 | E93: GPIO Mux | F93: MUX Output 31
A94: 93 | B94: =_xlfn.CONCAT(C94,"_",D94) -> PRESENT_1_PORT1 | C94: PRESENT_1 | D94: PORT1 | E94: Card detect 1
A95: 94 | B95: =_xlfn.CONCAT(C95,"_",D95) -> PRESENT_2_PORT1 | C95: PRESENT_2 | D95: PORT1 | E95: Card detect 1
A96: 95 | B96: =_xlfn.CONCAT(C96,"_",D96) -> PRESENT_1_PORT2 | C96: PRESENT_1 | D96: PORT2 | E96: Card detect 2
A97: 96 | B97: =_xlfn.CONCAT(C97,"_",D97) -> PRESENT_2_PORT2 | C97: PRESENT_2 | D97: PORT2 | E97: Card detect 2
A98: 97 | B98: =_xlfn.CONCAT(C98,"_",D98) -> PRESENT_1_PORT3 | C98: PRESENT_1 | D98: PORT3 | E98: Card detect 3
A99: 98 | B99: =_xlfn.CONCAT(C99,"_",D99) -> PRESENT_2_PORT3 | C99: PRESENT_2 | D99: PORT3 | E99: Card detect 3
A100: 99 | B100: =_xlfn.CONCAT(C100,"_",D100) -> PRESENT_1_PORT4 | C100: PRESENT_1 | D100: PORT4 | E100: Card detect 4
A101: 100 | B101: =_xlfn.CONCAT(C101,"_",D101) -> PRESENT_2_PORT4 | C101: PRESENT_2 | D101: PORT4 | E101: Card detect 5
A102: 101 | B102: =_xlfn.CONCAT(C102,"_",D102) -> SWO_PORT1 | C102: SWO | D102: PORT1
A103: 102 | B103: =_xlfn.CONCAT(C103,"_",D103) -> SWD_PORT1 | C103: SWD | D103: PORT1
A104: 103 | B104: =_xlfn.CONCAT(C104,"_",D104) -> SWO_PORT2 | C104: SWO | D104: PORT2
A105: 104 | B105: =_xlfn.CONCAT(C105,"_",D105) -> SWD_PORT2 | C105: SWD | D105: PORT2
A106: 105 | B106: =_xlfn.CONCAT(C106,"_",D106) -> SWO_PORT3 | C106: SWO | D106: PORT3
...
